Workbook

Sheet Mode demploi
B2: Imports Lagoon — Fichier de cadrage
B3: Référence commune Lagoon / So'Bloo : un onglet par import, à valider avant tout import de test.
B5: Comment remplir
B6: 1. So'Bloo a pré-rempli ses champs (colonnes bleues) : libellé affiché à l'écran, champ en base, format, obligatoire ou non, règle métier.
B7: 2. Lagoon complète les colonnes jaunes : champ Smile correspondant, à reprendre ou non, obligatoire, règle métier, exemple réel.
B8: 3. Lagoon ajoute en bas de chaque onglet les champs Smile absents de So'Bloo qu'elle souhaite reprendre (Origine = Smile).
B9: 4. Les lignes vertes (Origine = Smile) sont des besoins déjà remontés par Lagoon : champs à créer dans So'Bloo.
B10: 5. Les colonnes Origine, Format, Obligatoire, Règle, À reprendre et Statut sont des listes déroulantes.
B11: 6. Les règles sont revues ensemble en atelier ; le statut passe alors à « Validé ».
B12: Obligatoire = la ligne ne peut pas être importée sans ce champ. Les obligations conditionnelles et les valeurs par défaut sont précisées dans le détail de la règle. Source : code So'Bloo, branche develop du 06/10/2026.
B14: Légende
C15: Colonnes So'Bloo — pré-remplies par So'Bloo
C16: Colonnes Lagoon — à remplir par Lagoon
C17: Champ Smile identifié — à créer dans So'Bloo
B19: Exemple de ligne complétée par Lagoon
B20: Libellé So'Bloo | C20: Champ Smile | D20: À reprendre ? | E20: Obligatoire | F20: Règle Lagoon | G20: Détail de la règle Lagoon
B21: À créer : Accès limité | C21: restricted_access | D21: Oui | E21: Non | F21: Oui | G21: Si Oui : recharges d'achat (Liberté) bloquées en caisse au-delà du plafond. Exemple réel : client 100001
B22: Exemple fictif, pour illustrer le niveau de détail attendu.
B24: Avancement par onglet
B25: Onglet | C25: Lignes | D25: À traiter | E25: En discussion | F25: Validé | G25: Ordre d'import
B26: 1-Comptes comptables | C26: =COUNTA('1-Comptes comptables'!C6:C300) | D26: =COUNTIF('1-Comptes comptables'!R6:R300,"À traiter") | E26: =COUNTIF('1-Comptes comptables'!R6:R300,"En discussion") | F26: =COUNTIF('1-Comptes comptables'!R6:R300,"Validé") | G26: Lot 1
B27: 1b-Familles articles | C27: =COUNTA('1b-Familles articles'!C6:C300) | D27: =COUNTIF('1b-Familles articles'!R6:R300,"À traiter") | E27: =COUNTIF('1b-Familles articles'!R6:R300,"En discussion") | F27: =COUNTIF('1b-Familles articles'!R6:R300,"Validé") | G27: Lot 1
B28: 2-Clients | C28: =COUNTA('2-Clients'!C6:C300) | D28: =COUNTIF('2-Clients'!R6:R300,"À traiter") | E28: =COUNTIF('2-Clients'!R6:R300,"En discussion") | F28: =COUNTIF('2-Clients'!R6:R300,"Validé") | G28: Lot 2
B29: 3-Options articles | C29: =COUNTA('3-Options articles'!C6:C300) | D29: =COUNTIF('3-Options articles'!R6:R300,"À traiter") | E29: =COUNTIF('3-Options articles'!R6:R300,"En discussion") | F29: =COUNTIF('3-Options articles'!R6:R300,"Validé") | G29: Lot 3
B30: 4-Articles | C30: =COUNTA('4-Articles'!C6:C300) | D30: =COUNTIF('4-Articles'!R6:R300,"À traiter") | E30: =COUNTIF('4-Articles'!R6:R300,"En discussion") | F30: =COUNTIF('4-Articles'!R6:R300,"Validé") | G30: Lot 4
B31: 5-Réductions | C31: =COUNTA('5-Réductions'!C6:C300) | D31: =COUNTIF('5-Réductions'!R6:R300,"À traiter") | E31: =COUNTIF('5-Réductions'!R6:R300,"En discussion") | F31: =COUNTIF('5-Réductions'!R6:R300,"Validé") | G31: Lot 5
B32: 6-Abonnements | C32: =COUNTA('6-Abonnements'!C6:C300) | D32: =COUNTIF('6-Abonnements'!R6:R300,"À traiter") | E32: =COUNTIF('6-Abonnements'!R6:R300,"En discussion") | F32: =COUNTIF('6-Abonnements'!R6:R300,"Validé") | G32: Lot 6
B33: 6a-Abo Internet | C33: =COUNTA('6a-Abo Internet'!C6:C300) | D33: =COUNTIF('6a-Abo Internet'!R6:R300,"À traiter") | E33: =COUNTIF('6a-Abo Internet'!R6:R300,"En discussion") | F33: =COUNTIF('6a-Abo Internet'!R6:R300,"Validé") | G33: Lot 6
B34: 6b-Abo VOIP | C34: =COUNTA('6b-Abo VOIP'!C6:C300) | D34: =COUNTIF('6b-Abo VOIP'!R6:R300,"À traiter") | E34: =COUNTIF('6b-Abo VOIP'!R6:R300,"En discussion") | F34: =COUNTIF('6b-Abo VOIP'!R6:R300,"Validé") | G34: Lot 6
B35: Cas limites | C35: =COUNTA('Cas limites'!C6:C300) | D35: =COUNTIF('Cas limites'!H6:H300,"À traiter") | E35: =COUNTIF('Cas limites'!H6:H300,"En discussion") | F35: =COUNTIF('Cas limites'!H6:H300,"Validé") | G35: Tous
B36: Total | C36: =SUM(C26:C35) | D36: =SUM(D26:D35) | E36: =SUM(E26:E35) | F36: =SUM(F26:F35)

Sheet 1-Comptes comptables
A1: Comptes comptables
A2: Comptes généraux et comptes tiers. Importés en premier : familles, articles et clients y font référence. Aucun import autonome n'existe aujourd'hui (les imports actuels créent les comptes manquants avec le code seul) : import à développer.
B4: SO'BLOO — pré-rempli | L4: LAGOON — à compléter | R4: SUIVI COMMUN
A5: N° | B5: Origine | C5: Libellé So'Bloo (écran) | D5: Champ en base (tech) | E5: Description | F5: Format | G5: Valeurs possibles | H5: Obligatoire dans So'Bloo | I5: Règle métier So'Bloo | J5: Détail de la règle So'Bloo | K5: Exemple | L5: Champ Smile correspondant | M5: Champ à reprendre ? | N5: Obligatoire pour Lagoon | O5: Règle métier Lagoon | P5: Détail de la règle Lagoon | Q5: Exemple réel (ID Smile) | R5: Statut | S5: Commentaires
A6: 1 | B6: So'Bloo | C6: Compte général ou compte tiers (non affiché à l'écran) | D6: Choix de la table : general_accounting_account (Général) ou third_party_accounting_account (Tiers) | E6: Compte général ou compte tiers (auxiliaire) | F6: Liste | G6: Compte général / Compte tiers | H6: Oui | I6: Oui | J6: Ce n'est pas un champ mais le type de compte, qui détermine l'écran et la table : un compte général est un compte du plan comptable (7xxx, 44xx, 411 collectif…) ; un compte tiers est un compte auxiliaire individuel (ex. 411DUPONT), rattaché à un compte général via « Compte général associé » | K6: Général | R6: À traiter
A7: 2 | B7: So'Bloo | C7: Code (Comptes généraux / Comptes tiers › fenêtre de création) | D7: general_accounting_account.code ou third_party_accounting_account.code | E7: Numéro du compte | F7: Texte | H7: Oui | I7: Oui | J7: Numéro du compte (ex. 706100, 445710, 411000). Unique par organisation, séparément pour les comptes généraux et les comptes tiers, Y COMPRIS parmi les comptes supprimés (un code supprimé reste bloqué : il faut réactiver le compte). Plan Sage : 7XXX CA, 6XXX charges, 5XXX trésorerie, 44XX TGC, 41XX clients, 1XXX dépôts de garantie | K7: 707100 | R7: À traiter
A8: 3 | B8: So'Bloo | C8: Libellé (Comptes généraux / Comptes tiers › fenêtre de création) | D8: general_accounting_account.label ou third_party_accounting_account.label | E8: Intitulé du compte | F8: Texte | H8: Non | I8: Non | J8: Recommandé. Facultatif à l'écran ; les comptes créés par les imports actuels n'ont pas de libellé | K8: Ventes Internet particuliers | R8: À traiter
A9: 4 | B9: So'Bloo | C9: Type (Comptes généraux › fenêtre de création) | D9: general_accounting_account.type | E9: Usage du compte général | F9: Liste | G9: Clients et comptes rattachés / Clients, effets escomptes non échus / Ventes de produits fabriqués, prestations de services, marchandises / Taxes sur le chiffre d'affaires / Caisse / Banques / Rabais, remises et ristournes accordés par l'entreprise / Pertes / Profits / Fournisseurs / Dépôts de garantie / Débours refacturé | H9: Non | I9: Oui | J9: Obligatoire pour un compte général. Requis à l'écran. Vente, Remise et Débours sont marqués « analytique ». Sert à déterminer le compte par défaut | K9: Vente | R9: À traiter
A10: 5 | B10: So'Bloo | C10: Compte par défaut ? (Comptes généraux › fenêtre de création) | D10: general_accounting_account.is_default | E10: Compte utilisé quand ni l'article ni la famille n'ont de compte | F10: Oui/Non | H10: Non | I10: Oui | J10: Défaut : Non. Un seul compte par défaut par type et par organisation | K10: Non | R10: À traiter
A11: 6 | B11: So'Bloo | C11: Mensualisé ? (XXXXX01, XXXXXX02...) (Comptes généraux › fenêtre de création, visible seulement pour le type Clients, effets escomptes non échus) | D11: general_accounting_account.is_dynamic_per_month | E11: Déclinaison mensuelle du compte | F11: Oui/Non | H11: Non | I11: Oui | J11: Défaut : Non ; uniquement pour le type Clients non échus. Uniquement pour le type Client non échu : génère 12 comptes tiers dont la fin du code = n° du mois | K11: Non | R11: À traiter
A12: 7 | B12: So'Bloo | C12: Compte général associé (Comptes tiers › fenêtre de création) | D12: third_party_accounting_account.general_accounting_account_id | E12: Compte général auquel le compte tiers est rattaché | F12: Code de référence | H12: Non | I12: Oui | J12: Recommandé ; uniquement pour un compte tiers. Relation parent / enfant. Le compte collectif doit exister ou figurer plus haut dans le fichier | K12: 411000 | R12: À traiter
A13: 8 | B13: So'Bloo | C13: Organisation (non affiché à l'écran) | D13: general_accounting_account.organization_id ou third_party_accounting_account.organization_id | E13: Société / BU porteuse du compte | F13: Code de référence | H13: Oui | I13: Oui | J13: Pas de choix à l'écran : c'est l'organisation sélectionnée qui s'applique. Dans le fichier, indiquer l'organisation (Lagoon / Lagoon Business ?) | K13: Lagoon | R13: À traiter
A14: 9 | B14: So'Bloo | C14: Compte supprimé (non affiché à l'écran) | D14: general_accounting_account.is_deleted ou third_party_accounting_account.is_deleted | E14: Compte archivé | F14: Oui/Non | H14: Non | I14: Oui | J14: Défaut : Non. Suppression logique. Suppression refusée si le compte est affecté à un client | K14: Non | R14: À traiter
A15: 10 | B15: Smile | C15: À créer : Catégorie de rapport de vente | D15: À créer | E15: Regroupement Smile des ventes par compte | F15: Liste | I15: Oui | J15: À définir par Lagoon. Aucun équivalent dans So'bloo aujourd'hui (la ventilation passe par la famille). Lien catégorie ↔ compte à préciser par Lagoon | R15: À traiter
A16: 11 | B16: Smile | C16: À créer : Compte général parent | D16: À créer | E16: Double niveau demandé (atelier compta) | F16: Code de référence | I16: Oui | J16: À définir. Développement prévu, non présent dans le code actuel | R16: À traiter
B17: Smile
B18: Smile
B19: Smile
B20: Smile
B21: Smile
B22: Smile
B23: Smile
B24: Smile
B25: Smile
B26: Smile
B27: Smile
B28: Smile
... B31: Smile

Sheet 1b-Familles articles
A1: Familles d'articles
A2: Importées avec le lot 1 : elles portent les taxes et la ventilation comptable par défaut des articles.
B4: SO'BLOO — pré-rempli | L4: LAGOON — à compléter | R4: SUIVI COMMUN
A5: N° | B5: Origine | C5: Libellé So'Bloo (écran) | D5: Champ en base (tech) | E5: Description | F5: Format | G5: Valeurs possibles | H5: Obligatoire dans So'Bloo | I5: Règle métier So'Bloo | J5: Détail de la règle So'Bloo | K5: Exemple | L5: Champ Smile correspondant | M5: Champ à reprendre ? | N5: Obligatoire pour Lagoon | O5: Règle métier Lagoon | P5: Détail de la règle Lagoon | Q5: Exemple réel (ID Smile) | R5: Statut | S5: Commentaires
A6: 1 | B6: So'Bloo | C6: Libellé (Familles d'articles › Informations principales › Description) | D6: tag.label | E6: Nom de la famille | F6: Texte | H6: Oui | I6: Oui | J6: Unique (sans casse) au sein d'une même famille parente | K6: Abonnements Internet | R6: À traiter
A7: 2 | B7: So'Bloo | C7: Code (Familles d'articles › Informations principales › Description) | D7: tag.code | E7: Code unique de la famille | F7: Texte | H7: Oui | I7: Oui | J7: Unique parmi les familles actives. Converti automatiquement en minuscules | K7: abo-int | R7: À traiter
A8: 3 | B8: So'Bloo | C8: Type d’article (Familles d'articles › Informations principales › Description) | D8: tag.article_type | E8: Type proposé aux articles de la famille | F8: Liste | G8: Physique / Service / Abonnement / Débours / Frais / Chèque cadeau | H8: Oui | I8: Oui | J8: Requis à l'écran. Recopié sur l'article à l'import et à la saisie | K8: Abonnement | R8: À traiter
A9: 4 | B9: So'Bloo | C9: Groupe d’unité par défaut (Familles d'articles › Informations principales › Description) | D9: tag.unit_group | E9: Nature de l'unité | F9: Liste | G9: Comptage / Masse / Longueur / Surface / Volume / Temps | H9: Non | I9: Non | J9: Défaut : Comptage (pré-rempli à l'écran). Requis à l'écran | K9: Nombre | R9: À traiter
A10: 5 | B10: So'Bloo | C10: Index (Familles d'articles › Informations principales › Description) | D10: tag.idx | E10: Position dans les listes | F10: Nombre | H10: Non | I10: Non | J10: Requis à l'écran ; défaut proposé : numéro de ligne. Requis à l'écran | K10: 1 | R10: À traiter
A11: 6 | B11: So'Bloo | C11: Parent (Familles d'articles › Informations principales › Description) | D11: tag.parent_id | E11: Famille de niveau supérieur | F11: Code de référence | H11: Non | I11: Oui | J11: Doit exister ou figurer plus haut dans le fichier. Pas de cycle parent / enfant | R11: À traiter
A12: 7 | B12: So'Bloo | C12: Quel est le niveau unique de suivi pour cette famille ? (Familles d'articles › Informations principales, visible avec le module stock et hors type Service) | D12: tag.stock_tracking_type | E12: Suivi par défaut | F12: Liste | G12: Pas de niveau unique / Aucun suivi / Suivi global de l'article / Suivi par lot / Suivi par exemplaire / Suivi par exemplaire avec identification à la vente | H12: Non | I12: Non | J12: Défaut : Pas de niveau unique (vide) ; forcé à Aucun suivi pour Service et à Suivi par exemplaire pour Débours. Recopié une seule fois à la création de l'article (écran et import) ; aucune synchronisation ensuite. Débours impose le suivi par exemplaire | K12: Aucun | R12: À traiter
A13: 8 | B13: So'Bloo | C13: Famille (Paramètres › Taxes › fenêtre d'une taxe › « Associer cette taxe à une famille ») | D13: tax_tag.tax_id + tax_tag.tag_id | E13: Taxes héritées par les articles de la famille | F13: Liste multiple | G13: Taxes paramétrées dans Paramètres › Taxes | H13: Non | I13: Oui | J13: Ne figure pas sur la fiche famille : le lien se fait depuis Paramètres › Taxes (« Associer cette taxe à une famille »). Un article sans taxe propre hérite des taxes de ses familles. Une famille ne peut avoir deux taxes de même code | K13: TGC 22 % | R13: À traiter
A14: 9 | B14: So'Bloo | C14: Compte vente (Familles d'articles › Comptabilité › Comptes) ; « Compte débours » si type Débours | D14: tag_accounting.general_accounting_account_id (type=SALE ou DEBOURS, is_tax_exempt=false, organization_id) | E14: Compte de vente | F14: Code de référence | H14: Non | I14: Oui | J14: Doit exister (onglet 1). Priorité : compte de l'article > compte de la famille la plus fine > compte par défaut du type. ATTENTION : seules les familles directement rattachées à l'article sont lues (pas de remontée vers la famille parente). Pour une famille de type Débours, le champ devient « Compte débours » et les comptes exonéré / remise ne sont pas proposés | K14: 707100 | R14: À traiter
A15: 10 | B15: So'Bloo | C15: Compte vente exonéré (Familles d'articles › Comptabilité › Comptes) | D15: tag_accounting.general_accounting_account_id (type=SALE, is_tax_exempt=true, organization_id) | E15: Compte de vente si client exonéré | F15: Code de référence | H15: Non | I15: Oui | J15: Sans objet pour le type Débours. Utilisé si le devis / l'abonnement est exonéré de taxe | R15: À traiter
A16: 11 | B16: So'Bloo | C16: Compte remise (Familles d'articles › Comptabilité › Comptes) | D16: tag_accounting.general_accounting_account_id (type=DISCOUNT, is_tax_exempt=false, organization_id) | E16: Compte des remises | F16: Code de référence | H16: Non | I16: Oui | J16: Sans objet pour le type Débours. Les comptes de remise ne viennent que de la famille ou du compte par défaut | R16: À traiter
A17: 12 | B17: So'Bloo | C17: Compte remise exonéré (Familles d'articles › Comptabilité › Comptes) | D17: tag_accounting.general_accounting_account_id (type=DISCOUNT, is_tax_exempt=true, organization_id) | E17: Compte des remises, client exonéré | F17: Code de référence | H17: Non | I17: Oui | J17: Sans objet pour le type Débours | R17: À traiter
A18: 13 | B18: So'Bloo | C18: Formule (Familles d'articles › Informations principales › Désignation) | D18: tag.formula_to_create_label | E18: Génère le libellé des articles | F18: Texte | H18: Non | I18: Oui | J18: Si une seule famille porte une formule, le libellé de l'article est recalculé (sauf libellé forcé) | R18: À traiter
A19: 14 | B19: So'Bloo | C19: Gestion de la date de péremption pour les articles de cette famille ? (Familles d'articles › Informations principales › Traçabilité, visible si le paramètre article « date de péremption » est actif) | D19: tag.has_expiration_date | E19: Gestion DLC | F19: Oui/Non | H19: Non | I19: Non | J19: Défaut : Non. Sans objet pour Lagoon | K19: Non | R19: À traiter
B20: Smile
B21: Smile
B22: Smile
B23: Smile
B24: Smile
B25: Smile
B26: Smile
B27: Smile
B28: Smile
B29: Smile
B30: Smile
B31: Smile
... B34: Smile

Sheet 2-Clients
A1: Clients
A2: Particuliers et professionnels. La référence Smile est stockée dans la référence client et sert de clé de rapprochement (clé primaire).
B4: SO'BLOO — pré-rempli | L4: LAGOON — à compléter | R4: SUIVI COMMUN
A5: N° | B5: Origine | C5: Libellé So'Bloo (écran) | D5: Champ en base (tech) | E5: Description | F5: Format | G5: Valeurs possibles | H5: Obligatoire dans So'Bloo | I5: Règle métier So'Bloo | J5: Détail de la règle So'Bloo | K5: Exemple | L5: Champ Smile correspondant | M5: Champ à reprendre ? | N5: Obligatoire pour Lagoon | O5: Règle métier Lagoon | P5: Détail de la règle Lagoon | Q5: Exemple réel (ID Smile) | R5: Statut | S5: Commentaires
A6: 1 | B6: So'Bloo | C6: Réf. (Liste des clients) / « Client <réf> » (en-tête de la fiche client) | D6: customer.ref | E6: Identifiant client Smile (accountUsn) | F6: Code de référence | H6: Oui | I6: Oui | J6: CLÉ PRIMAIRE. Aucune unicité en base : dédoublonnage obligatoire avant import (un doublon casse les imports SEPA et Smile). Si vide, So'bloo génère plus tard C00001 / CF00001 | K6: 100001 | R6: À traiter
A7: 2 | B7: So'Bloo | C7: Type de client (Fiche client › Informations principales) | D7: customer.person_type | E7: Particulier ou professionnel | F7: Liste | G7: Particulier / Société | H7: Oui | I7: Oui | J7: Conditionne les champs obligatoires et les propriétés dynamiques. Particulier : libellé recalculé « Prénom Nom » | K7: Particulier | R7: À traiter
A8: 3 | B8: So'Bloo | C8: Civilité (non affiché à l'écran) | D8: customer.title | E8: M. / Mme | F8: Liste | G8: Monsieur / Madame | H8: Non | I8: Non | K8: Mme | R8: À traiter
A9: 4 | B9: So'Bloo | C9: Nom (Fiche client › Informations principales) | D9: customer.last_name | E9: Nom de famille | F9: Texte | H9: Non | I9: Oui | J9: Obligatoire si particulier. Exigé à l'import et à l'écran pour un particulier | K9: DUPONT | R9: À traiter
A10: 5 | B10: So'Bloo | C10: Prénom (Fiche client › Informations principales) | D10: customer.first_name | E10: Prénom | F10: Texte | H10: Non | I10: Oui | J10: Obligatoire si particulier. Idem | K10: Marie | R10: À traiter
A11: 6 | B11: So'Bloo | C11: Raison sociale (Fiche client › Informations principales) | D11: customer.label | E11: Nom de la société | F11: Texte | H11: Non | I11: Oui | J11: Obligatoire si société. Sert aussi à rattacher les contacts à l'import | K11: SARL EXEMPLE | R11: À traiter
A12: 7 | B12: So'Bloo | C12: Acronyme (Fiche client › Informations principales, société) | D12: customer.acronym | E12: Sigle | F12: Texte | H12: Non | I12: Non | R12: À traiter
A13: 8 | B13: So'Bloo | C13: Forme juridique (Fiche client › Informations principales, société) | D13: customer.legal_status_id | E13: SARL, SAS… | F13: Liste | G13: Référentiel Formes juridiques (paramétrable : SARL, SAS, …) | H13: Non | I13: Oui | J13: L'import actuel crée la valeur si elle est inconnue (attention aux fautes de frappe) | K13: SARL | R13: À traiter
A14: 9 | B14: So'Bloo | C14: Ridet (Fiche client › Informations principales, société) | D14: customer.ridet | E14: Identifiant entreprise NC | F14: Texte | H14: Non | I14: Oui | J14: Obligation paramétrable (société uniquement). Obligatoire pour un pro si le paramétrage du tenant l'exige. Aucun contrôle de format | K14: 1234567.001 | R14: À traiter
A15: 10 | B15: So'Bloo | C15: SIRET (non affiché à l'écran) | D15: customer.siret | E15: Identifiant entreprise métropole | F15: Texte | H15: Non | I15: Oui | J15: UNIQUE en base | R15: À traiter
A16: 11 | B16: So'Bloo | C16: Code APE (non affiché à l'écran) | D16: customer.ape | E16: Code APE | F16: Texte | H16: Non | I16: Non | R16: À traiter
A17: 12 | B17: So'Bloo | C17: Numéro RCS (non affiché à l'écran) | D17: customer.rcs_number | E17: Numéro RCS | F17: Texte | H17: Non | I17: Non | R17: À traiter
A18: 13 | B18: So'Bloo | C18: Ville RCS (non affiché à l'écran) | D18: customer.rcs_city | E18: Ville RCS | F18: Texte | H18: Non | I18: Non | R18: À traiter
A19: 14 | B19: So'Bloo | C19: Capital social (non affiché à l'écran) | D19: customer.social_capital | E19: Capital social | F19: Texte | H19: Non | I19: Non | R19: À traiter
A20: 15 | B20: So'Bloo | C20: Site internet (non affiché à l'écran) | D20: customer.website_url | E20: Site internet | F20: Texte | H20: Non | I20: Non | R20: À traiter
A21: 16 | B21: So'Bloo | C21: Email (Fiche client › Informations principales) | D21: customer.email | E21: Adresse e-mail principale | F21: E-mail | H21: Non | I21: Oui | J21: Obligation paramétrable ; obligatoire si « Coché par défaut comme destinataire facture ». Obligation paramétrable par tenant. Unicité contrôlée à l'écran selon paramétrage, pas à l'import. Aucun contrôle de format côté serveur : à ajouter au contrôle pré-import | K21: client@exemple.nc | R21: À traiter
A22: 17 | B22: So'Bloo | C22: Téléphone (Fiche client › Informations principales) | D22: customer.phone_number | E22: Téléphone fixe | F22: Téléphone | H22: Non | I22: Oui | J22: Obligation paramétrable. Normalisé à l'import : 6 chiffres → +687, 8 → +689, 10 → +33 | K22: 281234 | R22: À traiter
A23: 18 | B23: So'Bloo | C23: Mobile (Fiche client › Informations principales) | D23: customer.mobile_phone_number | E23: Téléphone mobile principal | F23: Téléphone | H23: Non | I23: Oui | J23: Obligation paramétrable. Un seul mobile (voir ligne mobiles multiples) | K23: 771234 | R23: À traiter
A24: 19 | B24: So'Bloo | C24: Date de naissance (Fiche client › Informations principales, particulier) | D24: customer.birth_date | E24: Date de naissance | F24: Date | H24: Non | I24: Oui | J24: Obligation paramétrable (particulier uniquement). Champs existants ; obligation paramétrable par tenant (à confirmer par Lagoon) | R24: À traiter
A25: 20 | B25: So'Bloo | C25: Lieu de naissance (Fiche client › Informations principales, particulier) | D25: customer.place_of_birth | E25: Lieu de naissance | F25: Texte | H25: Non | I25: Oui | J25: Obligation paramétrable (particulier uniquement) | R25: À traiter
A26: 21 | B26: So'Bloo | C26: Carte de fidélité, ou nom du programme de fidélité paramétré (Fiche client › Informations principales) | D26: customer.loyalty_card | E26: N° Conso+ | F26: Texte | H26: Non | I26: Oui | J26: UNIQUE en base | R26: À traiter
A27: 22 | B27: So'Bloo | C27: Badge « Prospect » (en-tête de la fiche client, non modifiable) | D27: customer.is_prospect | E27: Prospect ou client actif | F27: Oui/Non | H27: Non | I27: Oui | J27: Défaut : Oui si le tenant gère les prospects. Forcé à Oui à la création si le tenant gère les prospects : recalcul par batch après import (client actif si abonnement actif ou facture) | K27: Non | R27: À traiter
A28: 23 | B28: So'Bloo | C28: Bloqué (Fiche client › États) | D28: customer_states.blocking_date | E28: Date de blocage | F28: Date | H28: Non | I28: Oui | J28: Par organisation (customer_states.organization_id). Pas de liste de statuts : un état = des dates de blocage, contentieux, suspension. Non couvert par l'import actuel | R28: À traiter
A29: 24 | B29: So'Bloo | C29: Suspendu (Fiche client › États) | D29: customer_states.suspension_date | E29: Date de suspension | F29: Date | H29: Non | I29: Oui | J29: Par organisation | R29: À traiter
A30: 25 | B30: So'Bloo | C30: Contentieux (Fiche client › États) | D30: customer_states.litigation_date | E30: Date de mise en contentieux | F30: Date | H30: Non | I30: Oui | J30: Par organisation | R30: À traiter
A31: 26 | B31: So'Bloo | C31: Groupe de client (Fiche client › Affiliation à un groupe) | D31: customer_to_group.group_id | E31: Association, administration, grand compte, CE, employé… | F31: Liste multiple | G31: Référentiel Groupes de clients (paramétrable) | H31: Non | I31: Oui | J31: Les groupes doivent exister. Servent au moteur de réductions. Non couverts par l'import actuel | K31: EMPLOYE | R31: À traiter
A32: 27 | B32: So'Bloo | C32: « Ce client est associé à … » (en-tête de la fiche client, menu « Ajouter une association avec un client ») ; onglet Établissements du parent | D32: customer.parent_id | E32: Société mère / site | F32: Code de référence | H32: Non | I32: Oui | J32: L'enfant hérite des profils de paiement et des remises du parent. Le parent doit être importé avant | R32: À traiter
A33: 28 | B33: So'Bloo | C33: Adresse ligne 1 (Fiche client › Adresses › Ajouter une adresse) | D33: customer_address.address_line_1 | E33: Adresse ligne 1 | F33: Texte | H33: Non | I33: Non | J33: Obligatoire à l'écran pour toute adresse saisie. Plusieurs adresses possibles, sans type facturation / livraison | K33: 12 rue de l'Exemple | R33: À traiter
A34: 29 | B34: So'Bloo | C34: Adresse ligne 2 (Fiche client › Adresses) | D34: customer_address.address_line_2 | E34: Adresse ligne 2 | F34: Texte | H34: Non | I34: Non | R34: À traiter
A35: 30 | B35: So'Bloo | C35: Complément d'adresse (Fiche client › Adresses) | D35: customer_address.address_supplement | E35: Complément d'adresse | F35: Texte | H35: Non | I35: Non | R35: À traiter
A36: 31 | B36: So'Bloo | C36: Prénom et nom / Entreprise (Fiche client › Adresses) | D36: customer_address.address_label | E36: Destinataire de l'adresse | F36: Texte | H36: Non | I36: Non | J36: Obligatoire à l'écran ; défaut : libellé du client | R36: À traiter
A37: 32 | B37: So'Bloo | C37: Ville (Fiche client › Adresses) | D37: customer_address.city_label | E37: Ville | F37: Texte | H37: Non | I37: Non | J37: Obligatoire si module livraison (référentiel des villes). Libellés libres (pas les référentiels villes / codes postaux) | K37: Nouméa / 98800 | R37: À traiter
A38: 33 | B38: So'Bloo | C38: Code Postal (Fiche client › Adresses) | D38: customer_address.zip_code_label | E38: Code postal | F38: Texte | H38: Non | I38: Non | J38: Obligatoire si module livraison | R38: À traiter
A39: 34 | B39: So'Bloo | C39: Pays (Fiche client › Adresses) | D39: customer_address.country_label | E39: Pays | F39: Texte | H39: Non | I39: Non | R39: À traiter
A40: 35 | B40: So'Bloo | C40: Nom (Fiche client › Contacts › contact) | D40: contact.last_name | E40: Nom du contact | F40: Texte | H40: Non | I40: Oui | J40: Obligatoire pour tout contact importé. E-mail obligatoire si le contact est destinataire des factures. Un contact identique est refusé | R40: À traiter
A41: 36 | B41: So'Bloo | C41: Prénom (Fiche client › Contacts) | D41: contact.first_name | E41: Prénom du contact | F41: Texte | H41: Non | I41: Oui | R41: À traiter
...

Sheet 3-Options articles
A1: Options d'articles
A2: Importées avant les articles standards. Dans So'bloo, une option est un article (avec sa déclinaison et son prix) rattaché à l'article principal via un groupe d'options.
B4: SO'BLOO — pré-rempli | L4: LAGOON — à compléter | R4: SUIVI COMMUN
A5: N° | B5: Origine | C5: Libellé So'Bloo (écran) | D5: Champ en base (tech) | E5: Description | F5: Format | G5: Valeurs possibles | H5: Obligatoire dans So'Bloo | I5: Règle métier So'Bloo | J5: Détail de la règle So'Bloo | K5: Exemple | L5: Champ Smile correspondant | M5: Champ à reprendre ? | N5: Obligatoire pour Lagoon | O5: Règle métier Lagoon | P5: Détail de la règle Lagoon | Q5: Exemple réel (ID Smile) | R5: Statut | S5: Commentaires
A6: 1 | B6: So'Bloo | C6: Code article (Fiche article › Informations principales › Principales ; visible si le tenant a l'option « code article ») | D6: variant.code | E6: Code unique de l'option | F6: Texte | H6: Oui | I6: Oui | J6: CLÉ DE RAPPROCHEMENT. Unique sans casse parmi les déclinaisons actives (contrainte en base) | K6: OPT-IP-FIXE | R6: À traiter
A7: 2 | B7: So'Bloo | C7: Désignation (Fiche article › Informations principales › Principales) | D7: article.label + variant.label | E7: Nom de l'option | F7: Texte | H7: Oui | I7: Oui | J7: Seul champ bloquant de l'import Excel actuel | K7: Adresse IP fixe | R7: À traiter
A8: 3 | B8: So'Bloo | C8: Description (Fiche article › Informations principales › Principales) | D8: article.description | E8: Texte descriptif | F8: Texte | H8: Non | I8: Non | R8: À traiter
A9: 4 | B9: So'Bloo | C9: Type d'article (non affiché à l'écran) | D9: article.type | E9: Nature de l'option | F9: Liste | G9: Physique / Service / Abonnement / Débours / Frais / Chèque cadeau | H9: Non | I9: Oui | J9: Défaut : type de la famille. Débours impose un suivi par exemplaire | K9: Service | R9: À traiter
A10: 5 | B10: So'Bloo | C10: Famille (Fiche article › Informations principales › Principales ; ou étape « Quelle est la famille d’article ? » à la création si module stock) | D10: article_tag.tag_id (article_tag.article_id, idx=0) | E10: Famille d'articles | F10: Code de référence | H10: Non | I10: Oui | J10: Obligatoire si le paramètre tenant « famille obligatoire » (tagRequired) est actif. Doit exister (onglet 1b). Obligatoire si le paramètre tenant « famille obligatoire » est actif | K10: abo-int | R10: À traiter
A11: 6 | B11: So'Bloo | C11: Est une option (non affiché à l'écran) | D11: article.is_option | E11: L'article peut être proposé en option | F11: Oui/Non | H11: Non | I11: Oui | J11: Défaut : Non ; passe à Oui quand l'article est ajouté dans un groupe d'options. Positionné automatiquement quand l'article est ajouté à un groupe d'options (et retiré à sa suppression). En import direct, aucune valeur par défaut : envoyer Oui pour une option, Non sinon | K11: Oui | R11: À traiter
A12: 7 | B12: So'Bloo | C12: Disponiblité de l’article (Fiche article › Informations principales ; section visible selon le paramétrage des champs) | D12: article.is_option_only | E12: Ne se vend pas seul | F12: Liste | G12: Cet article est disponible en tant qu'article principal / Cet article est seulement disponible en tant qu'option | H12: Non | I12: Oui | J12: Défaut : article principal (Non). Champ non nul sans valeur par défaut : à fournir | K12: Oui | R12: À traiter
A13: 8 | B13: So'Bloo | C13: Type de prix (non affiché à l'écran) | D13: transaction_price.type | E13: Vente, abonnement ou package | F13: Liste | G13: Vente / Abonnement / Package | H13: Non | I13: Oui | J13: Défaut : Vente ; un seul prix par type (et par site). Un seul prix global par type | K13: Abonnement | R13: À traiter
A14: 9 | B14: So'Bloo | C14: Prix unitaire HT, ou Prix unitaire TTC selon la « Préférence de saisie de prix » (Fiche article › Tarification › Dernier prix en …) | D14: transaction_price.price_value (+ price_including_taxes_value si saisie TTC) | E14: Prix unitaire HT | F14: Montant | H14: Non | I14: Oui | J14: Obligatoire sauf si Prix libre = Oui. Montant et devise obligatoires. Saisie TTC possible | K14: 1000 | R14: À traiter
A15: 10 | B15: So'Bloo | C15: Devise (non affiché à l'écran) | D15: transaction_price.price_currency | E15: Devise du prix | F15: Code de référence | H15: Non | I15: Non | J15: Défaut : XPF. XPF | K15: XPF | R15: À traiter
A16: 11 | B16: So'Bloo | C16: Fréquence de facturation (Fiche article › Tarification › Dernier prix en abonnement) | D16: transaction_price.invoice_frequency_multiple + transaction_price.invoice_frequency_period | E16: Multiple + période (jour, semaine, mois, année) | F16: Liste | G16: 1 / 2 / 3 / 4 / 5 / 6 × mois / ans | H16: Non | I16: Oui | J16: Obligatoire si prix Abonnement. Non contrôlé par le serveur : à exiger à l'import pour un prix Abonnement | K16: 1 mois | R16: À traiter
A17: 12 | B17: So'Bloo | C17: Taxes (Fiche article › Tarification › Taxes, via « Cliquer ici pour modifier les taxes pour cet article ») | D17: article_tax.tax_id (article_tax.article_id) | E17: Taxes propres à l'option | F17: Liste multiple | G17: Taxes paramétrées dans Paramètres › Taxes | H17: Non | I17: Oui | J17: Défaut : taxes héritées de la famille. Si renseignées, remplacent totalement celles de la famille | R17: À traiter
A18: 13 | B18: So'Bloo | C18: Compte général (Fiche article › Comptabilité › Comptabilité ; visible avec le droit Comptabilité) | D18: article_accounting.general_accounting_account_id (article_accounting.article_id, organization_id) | E18: Surcharge du compte de la famille | F18: Code de référence | H18: Non | I18: Oui | J18: Défaut : compte de la famille. Prioritaire sur la famille, y compris pour un client exonéré | R18: À traiter
A19: 14 | B19: So'Bloo | C19: Actif (Fiche article › fenêtre de création › Principales) ; ensuite action « Supprimer » | D19: article.is_deleted (+ variant.is_deleted) | E19: Option obsolète | F19: Oui/Non | H19: Non | I19: Oui | J19: Défaut : actif (is_deleted = Non). Une option obsolète encore utilisée par un abonnement doit être importée | K19: Non | R19: À traiter
A20: 15 | B20: So'Bloo | C20: Quel niveau de suivi souhaitez-vous mettre en place ? (fenêtre de création d'article) | D20: article.with_stock_tracking + article.is_lot_tracked + article.is_single_tracked + article.is_single_tracked_on_sale | E20: Niveau de suivi de stock | F20: Liste | G20: Non, je ne gère pas le stock / Suivi global de l'article / Suivi par lot / Suivi par exemplaire / Suivi par exemplaire avec identification à la vente | H20: Non | I20: Oui | J20: Défaut : niveau de la famille, sinon aucun suivi | R20: À traiter
A21: 16 | B21: So'Bloo | C21: Unité de vente (Fiche article › Informations principales) | D21: variant.article_unit_reference_id | E21: Unité de vente | F21: Liste | G21: Unités paramétrées (selon le groupe d'unité) | H21: Non | I21: Oui | J21: Défaut : unité par défaut du groupe | R21: À traiter
A22: 17 | B22: So'Bloo | C22: Prix libre (Fiche article › Tarification › Dernier prix en …) | D22: transaction_price.is_open_price | E22: Prix libre | F22: Oui/Non | H22: Non | I22: Oui | J22: Défaut : Non | R22: À traiter
A23: 18 | B23: So'Bloo | C23: Préférence de saisie de prix (Fiche article › Tarification › Dernier prix en …) | D23: transaction_price.is_input_with_tax_included | E23: Préférence de saisie de prix | F23: Liste | G23: HT / TTC | H23: Non | I23: Oui | J23: Défaut : HT | R23: À traiter
A24: 19 | B24: So'Bloo | C24: Coût unitaire HT (Fiche article › Tarification › Coût unitaire / Coût de la prestation) | D24: variant.cost_value + variant.cost_currency | E24: Coût d'achat unitaire HT | F24: Montant | H24: Non | I24: Oui | J24: Requis à l'écran si non suivi en stock (défaut 0) | R24: À traiter
A25: 20 | B25: Smile | C25: À créer : Code variante | D25: À créer | E25: Si Lagoon utilise les variantes | F25: Texte | I25: Oui | J25: Si Lagoon utilise les variantes. Les variantes existent déjà dans So'Bloo (onglet « Variants » de la fiche article, si l'option est activée sur le tenant) : chaque variante a son propre code article. Choix de modélisation à faire avec Lagoon | R25: À traiter
A26: 21 | B26: Smile | C26: À créer : Dépendances entre options | D26: À créer | E26: Options obligatoires ou incompatibles | F26: Code de référence | I26: Oui | J26: À décrire par Lagoon. En partie couvert par les groupes d'options : « Type de sélection : Unique » rend les options d'un groupe incompatibles, « Une des options est obligatoire » rend le choix obligatoire. Seules les dépendances entre groupes seraient à créer | R26: À traiter
B27: Smile
B28: Smile
B29: Smile
B30: Smile
B31: Smile
B32: Smile
B33: Smile
B34: Smile
B35: Smile
B36: Smile
B37: Smile
B38: Smile
... B41: Smile

Sheet 4-Articles
A1: Articles standards
A2: Rattachés à leurs options. Comprend les frais fixes (mise en service, installation…). Une ligne = un article + sa déclinaison + son prix.
B4: SO'BLOO — pré-rempli | L4: LAGOON — à compléter | R4: SUIVI COMMUN
A5: N° | B5: Origine | C5: Libellé So'Bloo (écran) | D5: Champ en base (tech) | E5: Description | F5: Format | G5: Valeurs possibles | H5: Obligatoire dans So'Bloo | I5: Règle métier So'Bloo | J5: Détail de la règle So'Bloo | K5: Exemple | L5: Champ Smile correspondant | M5: Champ à reprendre ? | N5: Obligatoire pour Lagoon | O5: Règle métier Lagoon | P5: Détail de la règle Lagoon | Q5: Exemple réel (ID Smile) | R5: Statut | S5: Commentaires
A6: 1 | B6: So'Bloo | C6: Code article (Fiche article › Informations principales › Principales ; visible si le tenant a l'option « code article ») | D6: variant.code | E6: Code unique de l'article | F6: Texte | H6: Oui | I6: Oui | J6: CLÉ DE RAPPROCHEMENT. Unique sans casse parmi les déclinaisons actives. L'import actuel ne fait que créer (pas de mise à jour) : à faire évoluer pour le rejeu | K6: ALTO-PLUS | R6: À traiter
A7: 2 | B7: So'Bloo | C7: Désignation (Fiche article › Informations principales › Principales) | D7: article.label + variant.label | E7: Nom de l'article | F7: Texte | H7: Oui | I7: Oui | J7: Seul champ bloquant de l'import actuel ; libellé de déclinaison obligatoire | K7: Forfait Internet Alto+ | R7: À traiter
A8: 3 | B8: So'Bloo | C8: Description (Fiche article › Informations principales › Principales) ; « Conditions d’utilisation » pour un chèque cadeau | D8: article.description | E8: Texte descriptif | F8: Texte | H8: Non | I8: Non | R8: À traiter
A9: 4 | B9: So'Bloo | C9: Type d'article (non affiché à l'écran) | D9: article.type | E9: Nature de l'article | F9: Liste | G9: Physique / Service / Abonnement / Débours / Frais / Chèque cadeau | H9: Non | I9: Oui | J9: Défaut : type de la famille. À l'import, remplacé par le type de la famille. Débours impose un suivi par exemplaire | K9: Abonnement | R9: À traiter
A10: 5 | B10: So'Bloo | C10: Famille (Fiche article › Informations principales › Principales ; ou étape « Quelle est la famille d’article ? » à la création si module stock) | D10: article_tag.tag_id (article_tag.article_id, idx) | E10: Famille(s) d'articles | F10: Code de référence | H10: Non | I10: Oui | J10: Obligatoire si le paramètre tenant « famille obligatoire » est actif. Doit exister (onglet 1b). Plusieurs familles possibles ; la plus fine l'emporte pour la ventilation | K10: abo-int | R10: À traiter
A11: 6 | B11: So'Bloo | C11: Réf. externe (Fiche article › Informations principales › Principales ; visible pour un article Physique et seulement si le module Commandes fournisseurs est absent) | D11: variant.external_ref | E11: Référence fournisseur | F11: Texte | H11: Non | I11: Oui | J11: Ce n'est pas la référence fournisseur (voir onglet Fournisseurs). Unique sans casse. Masqué si le module Commandes fournisseurs est actif | R11: À traiter
A12: 7 | B12: So'Bloo | C12: Quel niveau de suivi souhaitez-vous mettre en place ? (fenêtre de création d'article) ; affiché ensuite en lecture seule dans « Suivi de l’article » (Informations principales) | D12: article.with_stock_tracking + article.is_lot_tracked + article.is_single_tracked + article.is_single_tracked_on_sale | E12: Aucun, global, par lot, par exemplaire | F12: Liste | G12: Non, je ne gère pas le stock / Suivi global de l'article / Suivi par lot / Suivi par exemplaire / Suivi par exemplaire avec identification à la vente | H12: Non | I12: Oui | J12: Défaut : niveau de la famille, sinon aucun suivi. Champs non nuls. Matériel (modem, routeur) suivi par exemplaire ; services non suivis. Non modifiable une fois des exemplaires créés | K12: Aucun | R12: À traiter
A13: 8 | B13: So'Bloo | C13: Coût unitaire HT (Fiche article › Tarification › Coût unitaire ; « Coût de la prestation » pour un service) | D13: variant.cost_value + variant.cost_currency | E13: Coût unitaire | F13: Montant | H13: Non | I13: Oui | J13: Requis à l'écran si l'article n'est pas suivi en stock (défaut 0). Ignoré si l'article est suivi en stock (coût issu des achats) | R13: À traiter
A14: 9 | B14: So'Bloo | C14: Fournisseur (Fiche article › Fournisseurs › Fournisseurs associés › Ajouter un article fournisseur) | D14: variant_supplier.supplier_id (variant_supplier.variant_id) | E14: Fournisseur principal | F14: Code de référence | H14: Non | I14: Oui | J14: Fournisseurs de l'article (plusieurs possibles), avec « Code article fournisseur » et « Désignation fournisseur » requis. Le fournisseur doit exister | R14: À traiter
A15: 10 | B15: So'Bloo | C15: Type de prix (non affiché à l'écran) | D15: transaction_price.type | E15: Vente, abonnement ou package | F15: Liste | G15: Vente / Abonnement / Package | H15: Non | I15: Oui | J15: Défaut : Vente ; un seul prix par type (et par site). Un seul prix global par type (et par entrepôt). Cas Alto+ : vendu uniquement en abonnement, sans prix de vente (problème ouvert) | K15: Abonnement | R15: À traiter
A16: 11 | B16: So'Bloo | C16: Prix unitaire HT, ou Prix unitaire TTC selon la « Préférence de saisie de prix » (Fiche article › Tarification › Dernier prix en …) | D16: transaction_price.price_value (+ price_including_taxes_value si saisie TTC) | E16: Prix unitaire HT | F16: Montant | H16: Non | I16: Oui | J16: Obligatoire sauf si Prix libre = Oui. Montant et devise obligatoires. Saisie TTC possible (HT recalculé). L'import actuel met 0 si vide | K16: 5000 | R16: À traiter
A17: 12 | B17: So'Bloo | C17: Devise (non affiché à l'écran) | D17: transaction_price.price_currency | E17: Devise du prix | F17: Code de référence | H17: Non | I17: Non | J17: Défaut : XPF | K17: XPF | R17: À traiter
A18: 13 | B18: So'Bloo | C18: Fréquence de facturation (Fiche article › Tarification › Dernier prix en abonnement) | D18: transaction_price.invoice_frequency_multiple + transaction_price.invoice_frequency_period | E18: Multiple + période + jour | F18: Liste | G18: 1 / 2 / 3 / 4 / 5 / 6 × mois / ans | H18: Non | I18: Oui | J18: Obligatoire si prix Abonnement. Non contrôlé par le serveur : à exiger à l'import pour un prix Abonnement. Deux prix d'une même commande s'additionnent seulement à fréquence égale | K18: 1 mois, le 1er | R18: À traiter
A19: 14 | B19: So'Bloo | C19: Prix libre (Fiche article › Tarification › Dernier prix en …) | D19: transaction_price.is_open_price | E19: Prix saisi à la vente | F19: Oui/Non | H19: Non | I19: Oui | J19: Défaut : Non ; impossible pour un débours. Si Non, un prix est exigé à l'écran | K19: Non | R19: À traiter
A20: 15 | B20: So'Bloo | C20: Éco-participation (Fiche article › Tarification › Dernier prix en vente) | D20: transaction_price.eco_contribution_id | E20: Éco-contribution rattachée | F20: Code de référence | H20: Non | I20: Oui | J20: Uniquement sur un prix Vente, avec les mêmes taxes que l'article | R20: À traiter
A21: 16 | B21: So'Bloo | C21: Taxes (Fiche article › Tarification › Taxes, via « Cliquer ici pour modifier les taxes pour cet article ») | D21: article_tax.tax_id (article_tax.article_id) | E21: Taxes propres à l'article | F21: Liste multiple | G21: Taxes paramétrées dans Paramètres › Taxes | H21: Non | I21: Oui | J21: Défaut : taxes héritées de la famille. Si renseignées, remplacent totalement celles de la famille ; sinon héritage | K21: TGC 22 % | R21: À traiter
A22: 17 | B22: So'Bloo | C22: Unité de vente (Fiche article › Informations principales ; affichée seulement si le groupe d'unité compte au moins 2 unités) | D22: variant.article_unit_reference_id | E22: Unité de vente | F22: Liste | G22: Unités paramétrées dans Paramètres › Unités (selon le groupe d'unité de la famille) | H22: Non | I22: Oui | J22: Défaut : unité par défaut du groupe. Unité par défaut du tenant si vide ; requise à l'écran | K22: Unité | R22: À traiter
A23: 18 | B23: So'Bloo | C23: Compte général (Fiche article › Comptabilité › Comptabilité ; visible avec le droit Comptabilité) | D23: article_accounting.general_accounting_account_id (article_accounting.article_id, organization_id) | E23: Surcharge du compte de la famille | F23: Code de référence | H23: Non | I23: Oui | J23: Défaut : compte de la famille. Prioritaire sur la famille, y compris client exonéré. Un compte par forfait demandé par Lagoon. Modification réservée aux droits Comptabilité | K23: 706100 | R23: À traiter
A24: 19 | B24: So'Bloo | C24: A des options (non affiché à l'écran) | D24: article.has_option | E24: L'article propose des options | F24: Oui/Non | H24: Non | I24: Oui | J24: Défaut : Non. Recalculé par le serveur seulement via l'écran : à positionner à l'import direct | K24: Oui | R24: À traiter
A25: 20 | B25: So'Bloo | C25: A une option obligatoire (non affiché à l'écran) | D25: article.has_option_required | E25: Une option doit être choisie | F25: Oui/Non | H25: Non | I25: Oui | J25: Défaut : Non. Idem | K25: Non | R25: À traiter
A26: 21 | B26: So'Bloo | C26: Nom du groupe (Fiche article › Options) | D26: option_group.label | E26: Nom du groupe d'options | F26: Texte | H26: Non | I26: Oui | J26: Obligatoire si l'article a des options | K26: Services complémentaires | R26: À traiter
A27: 22 | B27: So'Bloo | C27: Type de sélection pour les options (Fiche article › Options) | D27: option_group.is_unique | E27: Choix d'une seule ou de plusieurs options du groupe | F27: Liste | G27: Multiple / Unique | H27: Non | I27: Oui | J27: Défaut : Multiple. Unique = options du groupe incompatibles entre elles | K27: Unique | R27: À traiter
A28: 23 | B28: So'Bloo | C28: Une des options est obligatoire (Fiche article › Options) | D28: option_group.is_required | E28: Le client doit choisir une option du groupe | F28: Oui/Non | H28: Non | I28: Oui | J28: Proposé uniquement pour un groupe Unique. Défaut : Non | K28: Non | R28: À traiter
A29: 24 | B29: So'Bloo | C29: Sélection de l'article ou du service + Prix + « La quantité est obligatoirement égale à l’article » (Fiche article › Options › fenêtre Option) | D29: option.variant_id + option.transaction_price_id + option.is_quantity_from_parent (option.group_id) | E29: Codes des options du groupe | F29: Code de référence | H29: Non | I29: Oui | J29: Obligatoire si l'article a des options. Chaque option doit exister (onglet 3) et porte son propre prix dans le groupe. Quantité éventuellement reprise du parent | K29: OPT-IP-FIXE;OPT-HOTLINE | R29: À traiter
A30: 25 | B30: So'Bloo | C30: Garantie (Fiche article › Informations principales › Principales ; articles Physiques uniquement) | D30: article.guarantee | E30: Durée de garantie | F30: Nombre | H30: Non | I30: Non | R30: À traiter
A31: 26 | B31: So'Bloo | C31: Actif (Fiche article › fenêtre de création › Principales) ; ensuite action « Supprimer » | D31: article.is_deleted (+ variant.is_deleted) | E31: Article obsolète | F31: Oui/Non | H31: Non | I31: Oui | J31: Défaut : actif. Un article obsolète encore utilisé par un abonnement doit être importé | K31: Non | R31: À traiter
A32: 27 | B32: So'Bloo | C32: Préférence de saisie de prix (Fiche article › Tarification › Dernier prix en …) | D32: transaction_price.is_input_with_tax_included | E32: Préférence de saisie de prix | F32: Liste | G32: HT / TTC | H32: Non | I32: Oui | J32: Défaut : HT. Indique si le montant importé est HT ou TTC. | R32: À traiter
A33: 28 | B33: So'Bloo | C33: Dépôt de garantie (Fiche article › Tarification › Dernier prix en abonnement, bouton d'ajout) | D33: variant.deposit_price_value + variant.deposit_price_currency | E33: Dépôt de garantie | F33: Montant | H33: Non | I33: Oui | J33: Uniquement avec un prix Abonnement. Utile pour le matériel loué (box, décodeur). | R33: À traiter
A34: 29 | B34: So'Bloo | C34: Plafond de réduction (Fiche article › Tarification › Dernier prix en …) | D34: transaction_price.maximum_discount | E34: Plafond de réduction | F34: Pourcentage | H34: Non | I34: Non | R34: À traiter
A35: 30 | B35: So'Bloo | C35: Prix par site de stockage / Ajouter un site (Fiche article › Tarification › Dernier prix en vente ; si prix par site activé) | D35: transaction_price.warehouse_id | E35: Prix par site de stockage | F35: Code de référence | H35: Non | I35: Oui | J35: Vide = prix par défaut | R35: À traiter
A36: 31 | B36: So'Bloo | C36: Code article fournisseur (Fiche article › Fournisseurs › Ajouter un article fournisseur) | D36: variant_supplier.code | E36: Code article fournisseur | F36: Texte | H36: Non | I36: Oui | J36: Obligatoire si un fournisseur est renseigné | R36: À traiter
A37: 32 | B37: So'Bloo | C37: Désignation fournisseur (Fiche article › Fournisseurs › Ajouter un article fournisseur) | D37: variant_supplier.label | E37: Désignation fournisseur | F37: Texte | H37: Non | I37: Oui | J37: Obligatoire si un fournisseur est renseigné (défaut : désignation de l'article) | R37: À traiter
A38: 33 | B38: So'Bloo | C38: Marque (Fiche article › Informations principales › Principales ; articles Physiques, si marques activées) | D38: article.brand_id | E38: Marque | F38: Code de référence | H38: Non | I38: Non | R38: À traiter
A39: 34 | B39: So'Bloo | C39: Code-barres associés (Fiche article › Informations principales ; articles Physiques) | D39: variant_barcodes.barcode (variant_barcodes.variant_id) | E39: Code-barres | F39: Texte | H39: Non | I39: Oui | J39: Plusieurs valeurs possibles | R39: À traiter
A40: 35 | B40: So'Bloo | C40: Commentaire interne (Fiche article › Informations principales › Principales) | D40: variant.comment | E40: Commentaire interne | F40: Texte | H40: Non | I40: Non | R40: À traiter
A41: 36 | B41: So'Bloo | C41: Disponiblité de l’article (Fiche article › Informations principales) | D41: article.is_option_only | E41: Disponibilité de l'article | F41: Liste | G41: Cet article est disponible en tant qu'article principal / Cet article est seulement disponible en tant qu'option | H41: Non | I41: Oui | J41: Défaut : article principal. Colonne NOT NULL sans défaut JPA : l'import doit envoyer false. | R41: À traiter
...

Sheet 5-Réductions
A1: Réductions
A2: Fichier dédié, importé après les articles. Absentes des données actuelles : à fournir par Lagoon. Aucun import de réductions n'existe aujourd'hui.
B4: SO'BLOO — pré-rempli | L4: LAGOON — à compléter | R4: SUIVI COMMUN
A5: N° | B5: Origine | C5: Libellé So'Bloo (écran) | D5: Champ en base (tech) | E5: Description | F5: Format | G5: Valeurs possibles | H5: Obligatoire dans So'Bloo | I5: Règle métier So'Bloo | J5: Détail de la règle So'Bloo | K5: Exemple | L5: Champ Smile correspondant | M5: Champ à reprendre ? | N5: Obligatoire pour Lagoon | O5: Règle métier Lagoon | P5: Détail de la règle Lagoon | Q5: Exemple réel (ID Smile) | R5: Statut | S5: Commentaires
A6: 1 | B6: So'Bloo | C6: Code de la réduction (ID Smile) (non affiché à l'écran) | D6: discount.code | E6: Code unique de la réduction | F6: Code de référence | H6: Oui | I6: Oui | J6: Non affiché à l'écran. Un code renseigné classe la réduction en « code promo » (usage unique) : clé de rapprochement à porter autrement (à définir). Non unique en base | K6: RED-EMPLOYE | R6: À traiter
A7: 2 | B7: So'Bloo | C7: Nom de la réduction (Ventes › Réductions › fiche réduction) | D7: discount.label | E7: Nom de la réduction | F7: Texte | H7: Non | I7: Non | J7: Exigé à l'écran | K7: Remise employé | R7: À traiter
A8: 3 | B8: So'Bloo | C8: État (liste des Réductions ; actions « Valider cette promotion » / « Passer en brouillon ») | D8: discount.state | E8: Brouillon / Validée / Supprimée | F8: Liste | G8: Brouillon / Validée / Supprimée | H8: Non | I8: Oui | J8: Défaut : Brouillon (importer en Validée). Seules les réductions Validées s'appliquent : importer en Validée | K8: Validée | R8: À traiter
A9: 4 | B9: So'Bloo | C9: Applicable (fiche réduction, affiché seulement pour une réduction en Montant) | D9: discount.type | E9: Remise unitaire ou sur le total | F9: Liste | G9: Sur le prix de l'unité / Sur le total | H9: Non | I9: Oui | J9: Défaut : Sur le prix de l'unité | K9: Unitaire | R9: À traiter
A10: 5 | B10: So'Bloo | C10: Pourcentage de réduction (fiche réduction, Type de réduction = Pourcentage) | D10: discount_step.percentage | E10: Pourcentage de réduction | F10: Pourcentage | H10: Non | I10: Oui | J10: Obligatoire : pourcentage OU montant. Au moins un palier, avec un % > 0 ou un montant > 0 (le % prime si les deux) | K10: 100 % | R10: À traiter
A11: 6 | B11: So'Bloo | C11: Montant HT de réduction (fiche réduction, Type de réduction = Montant) | D11: discount_step.amount (+ discount_step.currency) | E11: Montant HT de réduction | F11: Montant | H11: Non | I11: Oui | J11: Obligatoire : pourcentage OU montant | R11: À traiter
A12: 7 | B12: So'Bloo | C12: À partir de (paliers, si « Avec dégressivité » = Oui) | D12: discount_step.quantity_threshold | E12: Palier de quantité | F12: Nombre | H12: Non | I12: Oui | J12: Défaut : 1. Le palier retenu est le plus haut seuil ≤ quantité | K12: 1 | R12: À traiter
A13: 8 | B13: So'Bloo | C13: Débute le (fiche réduction) | D13: discount.start_date | E13: Début de validité | F13: Date | H13: Non | I13: Oui | J13: Exigée à l'écran ; côté serveur, obligatoire si date de fin ou remise sans cible. Obligatoire si une date de fin est saisie, ou pour une remise sans cible | R13: À traiter
A14: 9 | B14: So'Bloo | C14: Termine le (fiche réduction) | D14: discount.end_date | E14: Fin de validité | F14: Date | H14: Non | I14: Oui | J14: ≥ date de début. Ex. premiers mois d'abonnement | R14: À traiter
A15: 10 | B15: So'Bloo | C15: Clients (fiche réduction, choix « Une sélection de clients ») | D15: discount_customer.customer_id | E15: Remise propre à un client | F15: Code de référence | H15: Non | I15: Oui | J15: S'applique aussi aux établissements enfants | R15: À traiter
A16: 11 | B16: So'Bloo | C16: Groupes clients (fiche réduction, « Une sélection de clients et de groupes de clients ») | D16: discount_customer_group.customer_group_id | E16: Remise par groupe (CE, employé…) | F16: Code de référence | H16: Non | I16: Oui | J16: Les groupes doivent exister | K16: EMPLOYE | R16: À traiter
A17: 12 | B17: So'Bloo | C17: Articles (fiche réduction, « Une sélection d'articles ») | D17: discount_variant.variant_id | E17: Remise sur des articles | F17: Code de référence | H17: Non | I17: Oui | J17: Chaque article doit exister (onglets 3 et 4) | K17: ALTO-PLUS | R17: À traiter
A18: 13 | B18: So'Bloo | C18: Marque (fiche réduction, « Une marque, une famille ») | D18: discount_brand_tag.brand_id | E18: Marque concernée | F18: Code de référence | H18: Non | I18: Oui | J18: Sans aucune cible : remise globale (une seule sans période par client ou article) | R18: À traiter
A19: 14 | B19: So'Bloo | C19: Famille (fiche réduction, « Une marque, une famille ») | D19: discount_brand_tag.tag_id | E19: Famille concernée | F19: Code de référence | H19: Non | I19: Oui | R19: À traiter
A20: 15 | B20: So'Bloo | C20: Règle de cumul (information) (non affiché à l'écran) | D20: Sans objet (règle du moteur de prix) | E20: Règle d'application | F20: Texte | H20: Non | I20: Oui | J20: Les remises NE SE CUMULENT PAS : So'bloo retient le prix le plus bas (contrat tarifaire prioritaire). Pas de remise automatique sur les articles de type Service | R20: À traiter
A21: 16 | B21: So'Bloo | C21: Compte comptable de remise (information) (non affiché à l'écran) | D21: Sans objet (compte Remise de la famille d'article ou compte par défaut) | E21: Compte comptable | F21: Code de référence | H21: Non | I21: Oui | J21: Pas de compte sur la réduction : il vient de la famille de l'article ou du compte Remise par défaut | R21: À traiter
A22: 17 | B22: So'Bloo | C22: Organisation (non affiché à l'écran) | D22: discount.organization_id | E22: Organisation | F22: Liste | G22: Lagoon / Lagoon Business | H22: Oui | I22: Oui | R22: À traiter
A23: 18 | B23: Smile | C23: À créer : Portée : article seul ou article + options | D23: À créer | E23: Validé en atelier 14 (employé = 100 % article et options) | F23: Liste | I23: Oui | J23: À vérifier dans le moteur actuel | R23: À traiter
A24: 19 | B24: Smile | C24: À créer : Réduction sur package (Alto+ et options) | D24: À créer | E24: Remise globale ou option « toutes options » | F24: Liste | I24: Oui | J24: À arbitrer ensemble (atelier 14) | R24: À traiter
B25: Smile
B26: Smile
B27: Smile
B28: Smile
B29: Smile
B30: Smile
B31: Smile
B32: Smile
B33: Smile
B34: Smile
B35: Smile
B36: Smile
... B39: Smile

Sheet 6-Abonnements
A1: Abonnements
A2: En cours uniquement, sans historique des factures. Dans So'bloo, un abonnement est un devis de type Abonnement avec ses lignes et son plan de facturation. Aucun import d'abonnements n'existe aujourd'hui.
B4: SO'BLOO — pré-rempli | L4: LAGOON — à compléter | R4: SUIVI COMMUN
A5: N° | B5: Origine | C5: Libellé So'Bloo (écran) | D5: Champ en base (tech) | E5: Description | F5: Format | G5: Valeurs possibles | H5: Obligatoire dans So'Bloo | I5: Règle métier So'Bloo | J5: Détail de la règle So'Bloo | K5: Exemple | L5: Champ Smile correspondant | M5: Champ à reprendre ? | N5: Obligatoire pour Lagoon | O5: Règle métier Lagoon | P5: Détail de la règle Lagoon | Q5: Exemple réel (ID Smile) | R5: Statut | S5: Commentaires
A6: 1 | B6: So'Bloo | C6: Numéro de marché (Abonnement › Informations supplémentaires) | D6: estimate.contract_number | E6: Numéro de marché de l'abonnement | F6: Code de référence | H6: Non | I6: Oui | J6: Ne pas y stocker l'ID Smile : le champ est visible et modifiable à l'écran. L'identifiant du contrat Smile est porté par le contrat d'abonnement (subscription_contract, voir plus bas) | R6: À traiter
A7: 2 | B7: So'Bloo | C7: Client (Abonnement) | D7: estimate.customer_id | E7: Client titulaire | F7: Code de référence | H7: Oui | I7: Oui | J7: Le client doit exister (onglet 2), sinon ligne rejetée | K7: 100001 | R7: À traiter
A8: 3 | B8: So'Bloo | C8: Établissement (colonne de la grille des lignes, si affichée ; « Modifier l'établissement ») | D8: estimate_line.customer_id | E8: Établissement du client par ligne | F8: Code de référence | H8: Non | I8: Oui | J8: Défaut : client de l'abonnement. Client enfant (établissement) ; recopié sur les commandes | R8: À traiter
A9: 4 | B9: So'Bloo | C9: État (liste des abonnements) ; badge en cours / inactif / Suspendu / Partiellement suspendu / Résilié | D9: estimate.state | E9: Validé / Suspendu / Partiellement suspendu | F9: Liste | G9: Validé / Suspendu / Partiellement suspendu | H9: Oui | I9: Oui | J9: Abonnements en cours = Validé. Un abonnement suspendu ne génère pas de commande. « Résilié » n'est pas un statut : il se déduit d'une date de fin passée | K9: Validé | R9: À traiter
A10: 5 | B10: So'Bloo | C10: Organisation (non affiché à l'écran) | D10: estimate.organization_id | E10: Lagoon / Lagoon Business | F10: Liste | G10: Lagoon / Lagoon Business | H10: Oui | I10: Oui | J10: Visible pour l'organisation définie | K10: Lagoon | R10: À traiter
A11: 6 | B11: So'Bloo | C11: Article (grille des lignes de l'abonnement) | D11: estimate_line.variant_id | E11: Code de l'article souscrit | F11: Code de référence | H11: Oui | I11: Oui | J11: Une ligne par article. Doit exister (onglet 4) | K11: ALTO-PLUS | R11: À traiter
A12: 7 | B12: So'Bloo | C12: Ajuster les options (tiroir d'options de la ligne) | D12: estimate_line.option_id (ligne enfant, estimate_line.parent_id) | E12: Options souscrites | F12: Code de référence | H12: Non | I12: Oui | J12: Une option est une ligne enfant de la ligne article (ligne parente + option). L'option doit être rattachée à l'article (onglet 4) | K12: OPT-IP-FIXE | R12: À traiter
A13: 8 | B13: So'Bloo | C13: « en abonnement » sous le prix de la ligne (non saisissable) | D13: estimate_line.transaction_type | E13: Vente, abonnement ou package | F13: Liste | G13: Vente / Abonnement / Package | H13: Non | I13: Oui | J13: Défaut : type du prix de transaction de l'article. Abonnement pour les lignes récurrentes | K13: Abonnement | R13: À traiter
